<?xml version="1.0"?>
<!-- This URDF was automatically created by SolidWorks to URDF Exporter! Originally created by Stephen Brawner (brawner@gmail.com) 
     Commit Version: 1.6.0-4-g7f85cfe  Build Version: 1.6.7995.38578
     For more information, please see http://wiki.ros.org/sw_urdf_exporter -->

<robot
  name="robot_model">
  <gazebo>
    <plugin name="gazebo_ros_control" filename="libgazebo_ros_control.so">
      <robotNamespace>/</robotNamespace>
    </plugin>
  </gazebo>
  
  <!-- Material definitions -->
  <material name="orange">
    <color rgba="0.5 0.0 0.5 1.0"/>
  </material>
  <material name="chassis_silver">
    <color rgba="0.78 0.80 0.82 1.0"/> 
  </material>
  <material name="body_color">
    <color rgba="0.50 0.60 0.10 1.0"/> 
  </material>
  <material name="metal_dark">
    <color rgba="0.35 0.36 0.38 1.0"/> 
  </material>
  <material name="mat_black">
    <color rgba="0.05 0.05 0.06 1.0"/> 
  </material>
  <material name="accent_blue">
    <color rgba="0.06 0.24 0.80 1.0"/> 
  </material>
  <material name="white">
    <color rgba="1.0 1.0 1.0 1.0"/>
  </material>

  <!-- ============================================================ -->
  <!-- Virtual Mobile Base Joints -->
  <!-- These joints allow the robot chassis to move in the XY plane -->
  <!-- and rotate around the Z axis (yaw) relative to the world frame -->
  <!-- ============================================================ -->
  
  <link name="world"/>
  
  <!-- Virtual link for X translation -->
  <link name="virtual_x_link">
    <inertial>
      <origin xyz="0 0 0" rpy="0 0 0"/>
      <mass value="0.001"/>
      <inertia ixx="0.0001" ixy="0" ixz="0" iyy="0.0001" iyz="0" izz="0.0001"/>
    </inertial>
  </link>
  
  <!-- Virtual link for Y translation -->
  <link name="virtual_y_link">
    <inertial>
      <origin xyz="0 0 0" rpy="0 0 0"/>
      <mass value="0.001"/>
      <inertia ixx="0.0001" ixy="0" ixz="0" iyy="0.0001" iyz="0" izz="0.0001"/>
    </inertial>
  </link>
  
  <!-- Virtual link for Yaw rotation -->
  <link name="virtual_yaw_link">
    <inertial>
      <origin xyz="0 0 0" rpy="0 0 0"/>
      <mass value="0.001"/>
      <inertia ixx="0.0001" ixy="0" ixz="0" iyy="0.0001" iyz="0" izz="0.0001"/>
    </inertial>
  </link>
  
  <!-- Joint 1: world -> virtual_x_link (X translation) -->
  <joint name="virtual_x_joint" type="prismatic">
    <parent link="world"/>
    <child link="virtual_x_link"/>
    <origin xyz="0 0 0" rpy="0 0 0"/>
    <axis xyz="1 0 0"/>
    <limit lower="-100" upper="100" effort="1000" velocity="10"/>
  </joint>
  
  <!-- Joint 2: virtual_x_link -> virtual_y_link (Y translation) -->
  <joint name="virtual_y_joint" type="prismatic">
    <parent link="virtual_x_link"/>
    <child link="virtual_y_link"/>
    <origin xyz="0 0 0" rpy="0 0 0"/>
    <axis xyz="0 1 0"/>
    <limit lower="-100" upper="100" effort="1000" velocity="10"/>
  </joint>
  
  <!-- Joint 3: virtual_y_link -> virtual_yaw_link (Yaw rotation) -->
  <joint name="virtual_yaw_joint" type="revolute">
    <parent link="virtual_y_link"/>
    <child link="virtual_yaw_link"/>
    <origin xyz="0 0 0.265" rpy="0 0 0"/>
    <axis xyz="0 0 1"/>
    <limit lower="-3.14159" upper="3.14159" effort="1000" velocity="3.14"/>
  </joint>
  
  <!-- Fixed joint from virtual_yaw_link to chassis_base_link -->
  <joint name="chassis_base_joint" type="fixed">
    <parent link="virtual_yaw_link"/>
    <child link="chassis_base_link"/>
    <origin xyz="0 0 0" rpy="0 0 0"/>
  </joint>
  
  <link
    name="chassis_base_link">
    <inertial>
      <origin
        xyz="-0.027237 -0.00044706 -0.13065"
        rpy="0 0 0" />
      <mass
        value="18.789" />
      <inertia
        ixx="0.32103"
        ixy="-0.00088596"
        ixz="0.0070426"
        iyy="0.35279"
        iyz="0.00010881"
        izz="0.63543" />
    </inertial>
    <visual>
      <origin
        xyz="0 0 0"
        rpy="0 0 0" />
      <geometry>
        <mesh
          filename="package://robot_model/meshes/chassis_base_link.STL" />
      </geometry>
      <material name="mat_black"/>
    </visual>
    <collision>
      <origin
        xyz="0 0 0"
        rpy="0 0 0" />
      <geometry>
        <mesh
          filename="package://robot_model/meshes/chassis_base_link.STL" />
      </geometry>
    </collision>
  </link>
  <link
    name="chassis_left_Link">
    <inertial>
      <origin
        xyz="4.996E-16 0.033322 0"
        rpy="0 0 0" />
      <mass
        value="2.8637" />
      <inertia
        ixx="0.0051541"
        ixy="-3.3608E-17"
        ixz="-1.1703E-17"
        iyy="0.0090798"
        iyz="-5.0051E-18"
        izz="0.0051541" />
    </inertial>
    <visual>
      <origin
        xyz="0 0 0"
        rpy="0 0 0" />
      <geometry>
        <mesh
          filename="package://robot_model/meshes/chassis_left_Link.STL" />
      </geometry>
      <material name="accent_blue"/>
    </visual>
    <collision>
      <origin
        xyz="0 0 0"
        rpy="0 0 0" />
      <geometry>
        <mesh
          filename="package://robot_model/meshes/chassis_left_Link.STL" />
      </geometry>
    </collision>
  </link>
  <joint
    name="chassis_left_Joint"
    type="fixed">
    <origin
      xyz="-0.041 0.1846 -0.1775"
      rpy="0 0 0" />
    <parent
      link="chassis_base_link" />
    <child
      link="chassis_left_Link" />
    <axis
      xyz="0 -1 0" />
  </joint>
  <link
    name="chassis_right_Link">
    <inertial>
      <origin
        xyz="-5.2736E-16 -0.033322 1.1102E-16"
        rpy="0 0 0" />
      <mass
        value="2.8637" />
      <inertia
        ixx="0.0051541"
        ixy="-3.3734E-17"
        ixz="1.0772E-17"
        iyy="0.0090798"
        iyz="5.0454E-18"
        izz="0.0051541" />
    </inertial>
    <visual>
      <origin
        xyz="0 0 0"
        rpy="0 0 0" />
      <geometry>
        <mesh
          filename="package://robot_model/meshes/chassis_right_Link.STL" />
      </geometry>
      <material name="accent_blue"/>
    </visual>
    <collision>
      <origin
        xyz="0 0 0"
        rpy="0 0 0" />
      <geometry>
        <mesh
          filename="package://robot_model/meshes/chassis_right_Link.STL" />
      </geometry>
    </collision>
  </link>
  <joint
    name="chassis_right_Joint"
    type="fixed">
    <origin
      xyz="-0.041 -0.1846 -0.1775"
      rpy="0 0 0" />
    <parent
      link="chassis_base_link" />
    <child
      link="chassis_right_Link" />
    <axis
      xyz="0 1 0" />
  </joint>
  <link
    name="trunk_base_link">
    <inertial>
      <origin
        xyz="-3.32739807928917E-11 0.00108475904249383 0.0646969570751819"
        rpy="0 0 0" />
      <mass
        value="5.2916725383757" />
      <inertia
        ixx="0.0204718891237549"
        ixy="4.85115711850459E-12"
        ixz="-6.41065846332626E-12"
        iyy="0.0225397707546832"
        iyz="-0.000166583637729049"
        izz="0.014637715325779" />
    </inertial>
    <visual>
      <origin
        xyz="0 0 0"
        rpy="0 0 0" />
      <geometry>
        <mesh
          filename="package://robot_model/meshes/base_link.STL" />
      </geometry>
      <material name="metal_dark"/>
    </visual>
    <collision>
      <origin
        xyz="0 0 0"
        rpy="0 0 0" />
      <geometry>
        <mesh
          filename="package://robot_model/meshes/base_link.STL" />
      </geometry>
    </collision>
  </link>
  <joint
    name="trunk_base_link_Joint"
    type="fixed">
    <origin
      xyz="0 0 0.0"
      rpy="0 0 0" />
    <parent
      link="chassis_base_link" />
    <child
      link="trunk_base_link" />
    <axis
      xyz="0 1 0" />
  </joint>
  <link
    name="Trunk_Link1">
    <inertial>
      <origin
        xyz="-2.00192633256768E-06 0.037648370852891 0.229389705349819"
        rpy="0 0 0" />
      <mass
        value="6.12532979899165" />
      <inertia
        ixx="0.107502593877351"
        ixy="-4.33428423533899E-07"
        ixz="1.55820301705163E-06"
        iyy="0.105834274643522"
        iyz="0.000834756143947899"
        izz="0.0138000958638935" />
    </inertial>
    <visual>
      <origin
        xyz="0 0 0"
        rpy="0 0 0" />
      <geometry>
        <mesh
          filename="package://robot_model/meshes/Trunk_Link1.STL" />
      </geometry>
      <material name="metal_dark"/>
    </visual>
    <collision>
      <origin
        xyz="0 0 0"
        rpy="0 0 0" />
      <geometry>
        <mesh
          filename="package://robot_model/meshes/Trunk_Link1.STL" />
      </geometry>
    </collision>
  </link>
  <joint
    name="Trunk_Joint1"
    type="revolute">
    <origin
      xyz="0 -0.0393 0.112"
      rpy="0 0 0" />
    <parent
      link="trunk_base_link" />
    <child
      link="Trunk_Link1" />
    <axis
      xyz="0 -1 0" />
    <limit
      lower="-1.57"
      upper="1.57"
      effort="300"
      velocity="15" />
    <dynamics
      damping="0.01"
      friction="0.1" />
  </joint>
  <link
    name="Trunk_Link2">
    <inertial>
      <origin
        xyz="6.93889390390723E-17 0.0527983940700079 0.181464564928581"
        rpy="0 0 0" />
      <mass
        value="4.75279692361668" />
      <inertia
        ixx="0.0610885753910733"
        ixy="-1.19536966653269E-18"
        ixz="-7.76730748312509E-18"
        iyy="0.0529989544087246"
        iyz="-0.00179309730212265"
        izz="0.0201482952717101" />
    </inertial>
    <visual>
      <origin
        xyz="0 0 0"
        rpy="0 0 0" />
      <geometry>
        <mesh
          filename="package://robot_model/meshes/Trunk_Link2.STL" />
      </geometry>
      <material name="metal_dark"/>
    </visual>
    <collision>
      <origin
        xyz="0 0 0"
        rpy="0 0 0" />
      <geometry>
        <mesh
          filename="package://robot_model/meshes/Trunk_Link2.STL" />
      </geometry>
    </collision>
  </link>
  <joint
    name="Trunk_Joint2"
    type="revolute">
    <origin
      xyz="0 -0.013 0.327"
      rpy="0 0 0" />
    <parent
      link="Trunk_Link1" />
    <child
      link="Trunk_Link2" />
    <axis
      xyz="0 1 0" />
    <limit
      lower="-1.57"
      upper="1.57"
      effort="300"
      velocity="15" />
    <dynamics
      damping="0.01"
      friction="0.1" />
  </joint>
  <link
    name="Trunk_Link3">
    <inertial>
      <origin
        xyz="1.69489079715479E-09 -0.0494999971490837 0.0299182901675204"
        rpy="0 0 0" />
      <mass
        value="1.40110394589238" />
      <inertia
        ixx="0.0039279902713771"
        ixy="-9.37102716068198E-12"
        ixz="1.60664128414939E-11"
        iyy="0.00456822897709997"
        iyz="-9.20676483539881E-11"
        izz="0.00233089385500014" />
    </inertial>
    <visual>
      <origin
        xyz="0 0 0"
        rpy="0 0 0" />
      <geometry>
        <mesh
          filename="package://robot_model/meshes/Trunk_Link3.STL" />
      </geometry>
      <material name="metal_dark"/>
    </visual>
    <collision>
      <origin
        xyz="0 0 0"
        rpy="0 0 0" />
      <geometry>
        <mesh
          filename="package://robot_model/meshes/Trunk_Link3.STL" />
      </geometry>
    </collision>
  </link>
  <joint
    name="Trunk_Joint3"
    type="revolute">
    <origin
      xyz="0 0.1018 0.255"
      rpy="0 0 0" />
    <parent
      link="Trunk_Link2" />
    <child
      link="Trunk_Link3" />
    <axis
      xyz="0 -1 0" />
    <limit
      lower="-1.57"
      upper="1.57"
      effort="300"
      velocity="15" />
    <dynamics
      damping="0.01"
      friction="0.1" />
  </joint>
  <link
    name="Trunk_Link4">
    <inertial>
      <origin
        xyz="-0.00657929165109954 2.61392266098781E-06 0.218245992580224"
        rpy="0 0 0" />
      <mass
        value="4.66047184585229" />
      <inertia
        ixx="0.0788874639537613"
        ixy="5.46530938736686E-10"
        ixz="0.00286825206797472"
        iyy="0.0515041942141216"
        iyz="3.46275348004213E-07"
        izz="0.0448953474115628" />
    </inertial>
    <visual>
      <origin
        xyz="0 0 0"
        rpy="0 0 0" />
      <geometry>
        <mesh
          filename="package://robot_model/meshes/Trunk_Link4.STL" />
      </geometry>
      <material name="invisible">
        <color rgba="0 0 0 0"/>
      </material>
    </visual>
    <collision>
      <origin
        xyz="0 0 0"
        rpy="0 0 0" />
      <geometry>
        <mesh
          filename="package://robot_model/meshes/Trunk_Link4.STL" />
      </geometry>
    </collision>
  </link>
  <joint
    name="Trunk_Joint4"
    type="revolute">
    <origin
      xyz="0 -0.0495 0.1005"
      rpy="0 0 0" />
    <parent
      link="Trunk_Link3" />
    <child
      link="Trunk_Link4" />
    <axis
      xyz="0 0 1" />
    <limit
      lower="-1.57"
      upper="1.57"
      effort="300"
      velocity="15" />
    <dynamics
      damping="0.01"
      friction="0.1" />
  </joint>
  <!-- 前后躯干 -->
  <link
    name="Trunk_Forward_Link4">
    <visual>
      <origin
        xyz="0 0 0"
        rpy="0 0 0" />
      <geometry>
        <mesh
          filename="package://robot_model/meshes/trunkforward.dae" />
      </geometry>
    </visual>
  </link>
  <joint
    name="Trunk_Forward_Joint4"
    type="fixed">
    <origin
      xyz="0.05 0.0 0.25"
      rpy="0 0 1.5708" />
    <parent
      link="Trunk_Link4" />
    <child
      link="Trunk_Forward_Link4" />
  </joint>
  <link
    name="Trunk_Back_Link4">
    <visual>
      <origin
        xyz="0 0 0"
        rpy="0 0 0" />
      <geometry>
        <mesh
          filename="package://robot_model/meshes/trunkback.dae" />
      </geometry>
    </visual>
  </link>
  <joint
    name="Trunk_Back_Joint4"
    type="fixed">
    <origin
      xyz="-0.1 -0.0 0.23"
      rpy="0 0 1.5708" />
    <parent
      link="Trunk_Link4" />
    <child
      link="Trunk_Back_Link4" />
  </joint>
  <link
    name="Head_Link1">
    <inertial>
      <origin
        xyz="-0.00027121 1.4012E-05 0.031017"
        rpy="0 0 0" />
      <mass
        value="0.25094" />
      <inertia
        ixx="6.0757E-05"
        ixy="-1.1281E-09"
        ixz="3.8393E-07"
        iyy="4.1675E-05"
        iyz="1.0479E-09"
        izz="6.523E-05" />
    </inertial>
    <visual>
      <origin
        xyz="0 0 0"
        rpy="0 0 0" />
      <geometry>
        <mesh
          filename="package://robot_model/meshes/Head_Link1.STL" />
      </geometry>
      <material name="metal_dark"/>
    </visual>
    <collision>
      <origin
        xyz="0 0 0"
        rpy="0 0 0" />
      <geometry>
        <mesh
          filename="package://robot_model/meshes/Head_Link1.STL" />
      </geometry>
    </collision>
  </link>
  <joint
    name="Head_Joint1"
    type="revolute">
    <origin
      xyz="-0.026 0 0.487"
      rpy="0 0 0" />
    <parent
      link="Trunk_Link4" />
    <child
      link="Head_Link1" />
    <axis
      xyz="0 0 1" />
    <limit
      lower="-1.57"
      upper="1.57"
      effort="15"
      velocity="15" />
    <dynamics
      damping="0.01"
      friction="0.1" />
  </joint>
  <link
    name="Head_Link2">
    <inertial>
      <origin
        xyz="1.3878E-16 -0.0243 0.093841"
        rpy="0 0 0" />
      <mass
        value="1.2686" />
      <inertia
        ixx="0.0042697"
        ixy="-4.6785E-20"
        ixz="-5.4624E-19"
        iyy="0.0031772"
        iyz="2.312E-19"
        izz="0.0013394" />
    </inertial>
    <visual>
      <origin
        xyz="0 0 0"
        rpy="0 0 0" />
      <geometry>
        <mesh
          filename="package://robot_model/meshes/Head_Link2.STL" />
      </geometry>
      <material name="metal_dark"/>
    </visual>
    <collision>
      <origin
        xyz="0 0 0"
        rpy="0 0 0" />
      <geometry>
        <mesh
          filename="package://robot_model/meshes/Head_Link2.STL" />
      </geometry>
    </collision>
  </link>
  <joint
    name="Head_Joint2"
    type="revolute">
    <origin
      xyz="0 0.0243 0.041"
      rpy="0 0 0" />
    <parent
      link="Head_Link1" />
    <child
      link="Head_Link2" />
    <axis
      xyz="0 -1 0" />
    <limit
      lower="-1.57"
      upper="1.57"
      effort="15"
      velocity="15" />
    <dynamics
      damping="0.01"
      friction="0.1" />
  </joint>
  <link
    name="Head_Forward_Link">
    <visual>
      <origin
        xyz="0 0 0"
        rpy="0 0 0" />
      <geometry>
        <mesh
          filename="package://robot_model/meshes/headforward.dae" />
      </geometry>
    </visual>
  </link>
  <joint
    name="Head_Forward_Joint"
    type="fixed">
    <origin
      xyz="0.0495 -0.023 0.115"
      rpy="0 0 1.5708" />
    <parent
      link="Head_Link2" />
    <child
      link="Head_Forward_Link" />
  </joint>
  <link
    name="Head_Eye_Link">
    <visual>
      <origin
        xyz="0 0 0"
        rpy="0 0 0" />
      <geometry>
        <box size="0.01 0.1 0.02" />
      </geometry>
      <material name="accent_blue"/>
    </visual>
  </link>
  <joint
    name="Head_Eye_Joint"
    type="fixed">
    <origin
      xyz="0.0745 -0.0235 0.13"
      rpy="0 0 0" />
    <parent
      link="Head_Link2" />
    <child
      link="Head_Eye_Link" />
  </joint>
  <link
    name="Head_Back_Link">
    <visual>
      <origin
        xyz="0 0 0"
        rpy="0 0 0" />
      <geometry>
        <mesh
          filename="package://robot_model/meshes/headback.dae" />
      </geometry>
    </visual>
  </link>
  <joint
    name="Head_Back_Joint"
    type="fixed">
    <origin
      xyz="-0.01 -0.024 0.1"
      rpy="0 0 1.57" />
    <parent
      link="Head_Link2" />
    <child
      link="Head_Back_Link" />
  </joint>
  <joint name="left_fixed" type="fixed">
    <parent link="Trunk_Link4"/>
    <child link="AR5_5_07L_base"/>
    <origin xyz="0.0 0.12 0.41" rpy="-1.57 1.57 0"/>
  </joint>
  <link name="AR5_5_07L_base">
    <visual>
      <geometry>
        <mesh filename="package://robot_model/meshes/AR5_P_L/AR5_5_07L_base.stl" scale="0.001 0.001 0.001"/>
      </geometry>
      <origin rpy="0 0 0" xyz="0.0 0.0 0.0"/>
      <material name="white"/>
    </visual>
    <inertial>
      <mass value="2.66"/>
      <inertia ixx="0.00484214" ixy="0.00000117" ixz="-0.00000044" iyy="0.00444297" iyz="-0.00000074" izz="0.00427071"/>
      <origin rpy="0 0 0" xyz="1.6e-05 -0.0006979999999999999 0.168185"/>
    </inertial>
    <collision>
      <geometry>
        <mesh filename="package://robot_model/meshes/AR5_P_L/AR5_5_07L_base.stl" scale="0.001 0.001 0.001"/>
      </geometry>
      <origin rpy="0 0 0" xyz="0.0 0.0 0.0"/>
    </collision>
  </link>
  <joint name="AR5_5_07L_joint_1" type="revolute">
    <parent link="AR5_5_07L_base"/>
    <child link="AR5_5_07L_link1"/>
    <limit effort="108" lower="-3.07" upper="3.07" velocity="3.490658503988659"/>
    <axis xyz="0 0 1"/>
    <origin rpy="0 0 0" xyz="0.0 0.0 0.0"/>
  </joint>
  <transmission name="ltran1">
    <type>transmission_interface/SimpleTransmission</type>
    <joint name="AR5_5_07L_joint_1">
      <hardwareInterface>EffortJointInterface</hardwareInterface>
    </joint>
    <actuator name="lmotor1">
      <hardwareInterface>EffortJointInterface</hardwareInterface>
      <mechanicalReduction>1</mechanicalReduction>
    </actuator>
  </transmission>
  <!--link 1-->
  <link name="AR5_5_07L_link1">
    <visual>
      <geometry>
        <mesh filename="package://robot_model/meshes/AR5_P_L/AR5_5_07L_link1.stl" scale="0.001 0.001 0.001"/>
      </geometry>
      <origin rpy="0 0 0" xyz="0 0 0"/>
      <material name="white"/>
    </visual>
    <inertial>
      <mass value="2.66"/>
      <inertia ixx="0.00484214" ixy="0.00000117" ixz="-0.00000044" iyy="0.00444297" iyz="-0.00000074" izz="0.00427071"/>
      <origin rpy="0 0 0" xyz="1.6e-05 -0.0006979999999999999 0.168185"/>
    </inertial>
    <collision>
      <geometry>
        <mesh filename="package://robot_model/meshes/AR5_P_L/AR5_5_07L_link1.stl" scale="0.001 0.001 0.001"/>
      </geometry>
      <origin rpy="0 0 0" xyz="0 0 0"/>
    </collision>
  </link>
  <joint name="AR5_5_07L_joint_2" type="revolute">
    <parent link="AR5_5_07L_link1"/>
    <child link="AR5_5_07L_link2"/>
    <limit effort="108" lower="-2.06" upper="2.06" velocity="3.490658503988659"/>
    <axis xyz="0 1 0"/>
    <origin rpy="0 0 0" xyz="0.0 0.0 0.1745"/>
  </joint>
  <transmission name="ltran2">
    <type>transmission_interface/SimpleTransmission</type>
    <joint name="AR5_5_07L_joint_2">
      <hardwareInterface>EffortJointInterface</hardwareInterface>
    </joint>
    <actuator name="lmotor2">
      <hardwareInterface>EffortJointInterface</hardwareInterface>
      <mechanicalReduction>1</mechanicalReduction>
    </actuator>
  </transmission>
  <!--link 2-->
  <link name="AR5_5_07L_link2">
    <visual>
      <geometry>
        <mesh filename="package://robot_model/meshes/AR5_P_L/AR5_5_07L_link2.stl" scale="0.001 0.001 0.001"/>
      </geometry>
      <origin rpy="0 0 0" xyz="0 0 0.0"/>
      <material name="white"/>
    </visual>
    <inertial>
      <mass value="2.3"/>
      <inertia ixx="0.01155422" ixy="0.00000028" ixz="-0.00000103" iyy="0.00995119" iyz="0.00083831" izz="0.00437076"/>
      <origin rpy="0 0 0" xyz="4.4999999999999996e-05 -0.002985 0.102801"/>
    </inertial>
    <collision>
      <geometry>
        <mesh filename="package://robot_model/meshes/AR5_P_L/AR5_5_07L_link2.stl" scale="0.001 0.001 0.001"/>
      </geometry>
      <origin rpy="0 0 0" xyz="0 0 0.0"/>
    </collision>
  </link>
  <joint name="AR5_5_07L_joint_3" type="revolute">
    <parent link="AR5_5_07L_link2"/>
    <child link="AR5_5_07L_link3"/>
    <limit effort="66" lower="-3.07" upper="3.07" velocity="4.71238898038469"/>
    <axis xyz="0 0 1"/>
    <origin rpy="0 0 0" xyz="0.0 0.0 0.314"/>
  </joint>
  <transmission name="ltran3">
    <type>transmission_interface/SimpleTransmission</type>
    <joint name="AR5_5_07L_joint_3">
      <hardwareInterface>EffortJointInterface</hardwareInterface>
    </joint>
    <actuator name="lmotor3">
      <hardwareInterface>EffortJointInterface</hardwareInterface>
      <mechanicalReduction>1</mechanicalReduction>
    </actuator>
  </transmission>
  <!--link 3-->
  <link name="AR5_5_07L_link3">
    <visual>
      <geometry>
        <mesh filename="package://robot_model/meshes/AR5_P_L/AR5_5_07L_link3.stl" scale="0.001 0.001 0.001"/>
      </geometry>
      <origin rpy="0 0 0" xyz="0 0 0"/>
      <material name="white"/>
    </visual>
    <inertial>
      <mass value="1.8"/>
      <inertia ixx="0.00478231" ixy="0.00001317" ixz="0.00033105" iyy="0.00432575" iyz="0.00002132" izz="0.00254969"/>
      <origin rpy="0 0 0" xyz="0.0073 -0.001371 -0.01502"/>
    </inertial>
    <collision>
      <geometry>
        <mesh filename="package://robot_model/meshes/AR5_P_L/AR5_5_07L_link3.stl" scale="0.001 0.001 0.001"/>
      </geometry>
      <origin rpy="0 0 0" xyz="0 0 0"/>
    </collision>
  </link>
  <joint name="AR5_5_07L_joint_4" type="revolute">
    <parent link="AR5_5_07L_link3"/>
    <child link="AR5_5_07L_link4"/>
    <limit effort="66" lower="-1.01" upper="2.5" velocity="5.235987755982989"/>
    <!--     lower="-1.0472" upper="1.0472" -->
    <axis xyz="0 1 0"/>
    <!--     <origin rpy="0 0 0" xyz=0.0105 0.0 0.0/> -->
    <origin rpy="0 0 0" xyz="0.0105 0.0 0.0"/>
  </joint>
  <transmission name="ltran4">
    <type>transmission_interface/SimpleTransmission</type>
    <joint name="AR5_5_07L_joint_4">
      <hardwareInterface>EffortJointInterface</hardwareInterface>
    </joint>
    <actuator name="lmotor4">
      <hardwareInterface>EffortJointInterface</hardwareInterface>
      <mechanicalReduction>1</mechanicalReduction>
    </actuator>
  </transmission>
  <!--link 4-->
  <link name="AR5_5_07L_link4">
    <visual>
      <geometry>
        <mesh filename="package://robot_model/meshes/AR5_P_L/AR5_5_07L_link4.stl" scale="0.001 0.001 0.001"/>
      </geometry>
      <origin rpy="0 0 0" xyz="0.0 0.0 0.0"/>
      <material name="white"/>
    </visual>
    <inertial>
      <mass value="1.13"/>
      <inertia ixx="0.00352152" ixy="-0.00002411" ixz="-0.00015046" iyy="0.00266275" iyz="0.00025447" izz="0.00186915"/>
      <origin rpy="0 0 0" xyz="-0.007816 -0.002536 0.066782"/>
    </inertial>
    <collision>
      <geometry>
        <mesh filename="package://robot_model/meshes/AR5_P_L/AR5_5_07L_link4.stl" scale="0.001 0.001 0.001"/>
      </geometry>
      <origin rpy="0 0 0" xyz="0.0 0.0 0.0"/>
    </collision>
  </link>
  <joint name="AR5_5_07L_joint_5" type="revolute">
    <parent link="AR5_5_07L_link4"/>
    <child link="AR5_5_07L_link5"/>
    <limit effort="19" lower="-3.07" upper="3.07" velocity="4.1887902047863905"/>
    <axis xyz="0 0 1"/>
    <origin rpy="0 0 0" xyz="-0.0105 0.0 0.26"/>
  </joint>
  <transmission name="ltran5">
    <type>transmission_interface/SimpleTransmission</type>
    <joint name="AR5_5_07L_joint_5">
      <hardwareInterface>EffortJointInterface</hardwareInterface>
    </joint>
    <actuator name="lmotor5">
      <hardwareInterface>EffortJointInterface</hardwareInterface>
      <mechanicalReduction>1</mechanicalReduction>
    </actuator>
  </transmission>
  <!--link 5-->
  <link name="AR5_5_07L_link5">
    <visual>
      <geometry>
        <mesh filename="package://robot_model/meshes/AR5_P_L/AR5_5_07L_link5.stl" scale="0.001 0.001 0.001"/>
      </geometry>
      <origin rpy="0 0 0" xyz="0 0 0"/>
      <material name="white"/>
    </visual>
    <inertial>
      <mass value="1.19"/>
      <inertia ixx="0.00238316" ixy="0.00001280" ixz="0.00001311" iyy="0.00195453" iyz="0.00001458" izz="0.00149979"/>
      <origin rpy="0 0 0" xyz="0.00023400000000000002 0.002477 -0.08120000000000001"/>
    </inertial>
    <collision>
      <geometry>
        <mesh filename="package://robot_model/meshes/AR5_P_L/AR5_5_07L_link5.stl" scale="0.001 0.001 0.001"/>
      </geometry>
      <origin rpy="0 0 0" xyz="0 0 0"/>
    </collision>
  </link>
  <joint name="AR5_5_07L_joint_6" type="revolute">
    <parent link="AR5_5_07L_link5"/>
    <child link="AR5_5_07L_link6"/>
    <limit effort="19" lower="-1.01" upper="1.01" velocity="4.1887902047863905"/>
    <axis xyz="0 1 0"/>
    <origin rpy="0.0 0.0 0" xyz="0.0 0.0 0.0"/>
  </joint>
  <transmission name="ltran6">
    <type>transmission_interface/SimpleTransmission</type>
    <joint name="AR5_5_07L_joint_6">
      <hardwareInterface>EffortJointInterface</hardwareInterface>
    </joint>
    <actuator name="lmotor6">
      <hardwareInterface>EffortJointInterface</hardwareInterface>
      <mechanicalReduction>1</mechanicalReduction>
    </actuator>
  </transmission>
  <!--link 6-->
  <link name="AR5_5_07L_link6">
    <visual>
      <geometry>
        <mesh filename="package://robot_model/meshes/AR5_P_L/AR5_5_07L_link6.stl" scale="0.001 0.001 0.001"/>
      </geometry>
      <origin rpy="0 0 0" xyz="0 0 0"/>
      <material name="white"/>
    </visual>
    <inertial>
      <mass value="0.82"/>
      <inertia ixx="0.00060715" ixy="-0.00000829" ixz="0.00000078" iyy="0.00065671" iyz="0.00000017" izz="0.00066165"/>
      <origin rpy="0 0 0" xyz="0.0072039999999999995 0.0007149999999999999 -4e-05"/>
    </inertial>
    <collision>
      <geometry>
        <mesh filename="package://robot_model/meshes/AR5_P_L/AR5_5_07L_link6.stl" scale="0.001 0.001 0.001"/>
      </geometry>
      <origin rpy="0 0 0" xyz="0 0 0"/>
    </collision>
  </link>
  <joint name="AR5_5_07L_joint_7" type="revolute">
    <parent link="AR5_5_07L_link6"/>
    <child link="AR5_5_07L_link7"/>
    <limit effort="19" lower="-1.01" upper="1.01" velocity="4.1887902047863905"/>
    <axis xyz="1 0 0"/>
    <origin rpy="0.0 0.0 0" xyz="0.0 0.0 0.0"/>
  </joint>
  <transmission name="ltran7">
    <type>transmission_interface/SimpleTransmission</type>
    <joint name="AR5_5_07L_joint_7">
      <hardwareInterface>EffortJointInterface</hardwareInterface>
    </joint>
    <actuator name="lmotor7">
      <hardwareInterface>EffortJointInterface</hardwareInterface>
      <mechanicalReduction>1</mechanicalReduction>
    </actuator>
  </transmission>
  <!--link 7-->
  <link name="AR5_5_07L_link7">
    <visual>
      <geometry>
        <mesh filename="package://robot_model/meshes/AR5_P_L/AR5_5_07L_link7.stl" scale="0.001 0.001 0.001"/>
      </geometry>
      <origin rpy="0 0 0" xyz="0.0 0.0 0.0"/>
      <material name="white"/>
    </visual>
    <inertial>
      <mass value="0.32"/>
      <inertia ixx="0.00043581" ixy="0.00000007" ixz="0.00001201" iyy="0.00067064" iyz="0.00000188" izz="0.00041740"/>
      <origin rpy="0 0 0" xyz="-0.002337 0.000307 0.051645"/>
    </inertial>
    <collision>
      <geometry>
        <mesh filename="package://robot_model/meshes/AR5_P_L/AR5_5_07L_link7.stl" scale="0.001 0.001 0.001"/>
      </geometry>
      <origin rpy="0 0 0" xyz="0.0 0.0 0.0"/>
    </collision>
  </link>
  <joint name="AR5_5_07L_tcp_joint" type="fixed">
    <parent link="AR5_5_07L_link7"/>
    <child link="AR5_5_07L_tcp"/>
    <origin rpy="0 0 0" xyz="0.0 0.0 0.092"/>
  </joint>
  <link name="AR5_5_07L_tcp">
    <inertial>
      <mass value="0.0"/>
      <inertia ixx="1e-6" ixy="0" ixz="0" iyy="1e-6" iyz="0" izz="1e-6"/>
    </inertial>
  </link>

  <joint name="right_fixed" type="fixed">
    <parent link="Trunk_Link4"/>
    <child link="AR5_5_07R_base"/>
    <origin xyz="0.0 -0.12 0.41" rpy="1.57 1.57 0"/>
  </joint>
  <link name="AR5_5_07R_base">
    <visual>
      <geometry>
        <mesh filename="package://robot_model/meshes/AR5_P_R/AR5_5_07R_base.stl" scale="0.001 0.001 0.001"/>
      </geometry>
      <origin rpy="0 0 0" xyz="0.0 0.0 0.0"/>
      <material name="white"/>
    </visual>
    <inertial>
      <mass value="2.66"/>
      <inertia ixx="0.00484214" ixy="0.00000117" ixz="-0.00000044" iyy="0.00444297" iyz="-0.00000074" izz="0.00427071"/>
      <origin rpy="0 0 0" xyz="1.6e-05 -0.0006979999999999999 0.168185"/>
    </inertial>
    <collision>
      <geometry>
        <mesh filename="package://robot_model/meshes/AR5_P_R/AR5_5_07R_base.stl" scale="0.001 0.001 0.001"/>
      </geometry>
      <origin rpy="0 0 0" xyz="0.0 0.0 0.0"/>
    </collision>
  </link>
  <joint name="AR5_5_07R_joint_1" type="revolute">
    <parent link="AR5_5_07R_base"/>
    <child link="AR5_5_07R_link1"/>
    <limit effort="108" lower="-3.07" upper="3.07" velocity="3.490658503988659"/>
    <axis xyz="0 0 1"/>
    <origin rpy="0 0 0" xyz="0.0 0.0 0.0"/>
  </joint>
  <transmission name="rtran1">
    <type>transmission_interface/SimpleTransmission</type>
    <joint name="AR5_5_07R_joint_1">
      <hardwareInterface>EffortJointInterface</hardwareInterface>
    </joint>
    <actuator name="rmotor1">
      <hardwareInterface>EffortJointInterface</hardwareInterface>
      <mechanicalReduction>1</mechanicalReduction>
    </actuator>
  </transmission>
  <!--link 1-->
  <link name="AR5_5_07R_link1">
    <visual>
      <geometry>
        <mesh filename="package://robot_model/meshes/AR5_P_R/AR5_5_07R_link1.stl" scale="0.001 0.001 0.001"/>
      </geometry>
      <origin rpy="0 0 0" xyz="0 0 0"/>
      <material name="white"/>
    </visual>
    <inertial>
      <mass value="2.66"/>
      <inertia ixx="0.00484214" ixy="0.00000117" ixz="-0.00000044" iyy="0.00444297" iyz="-0.00000074" izz="0.00427071"/>
      <origin rpy="0 0 0" xyz="1.6e-05 -0.0006979999999999999 0.168185"/>
    </inertial>
    <collision>
      <geometry>
        <mesh filename="package://robot_model/meshes/AR5_P_R/AR5_5_07R_link1.stl" scale="0.001 0.001 0.001"/>
      </geometry>
      <origin rpy="0 0 0" xyz="0 0 0"/>
    </collision>
  </link>
  <joint name="AR5_5_07R_joint_2" type="revolute">
    <parent link="AR5_5_07R_link1"/>
    <child link="AR5_5_07R_link2"/>
    <limit effort="108" lower="-2.06" upper="2.06" velocity="3.490658503988659"/>
    <axis xyz="0 1 0"/>
    <origin rpy="0 0 0" xyz="0.0 0.0 0.1745"/>
  </joint>
  <transmission name="rtran2">
    <type>transmission_interface/SimpleTransmission</type>
    <joint name="AR5_5_07R_joint_2">
      <hardwareInterface>EffortJointInterface</hardwareInterface>
    </joint>
    <actuator name="rmotor2">
      <hardwareInterface>EffortJointInterface</hardwareInterface>
      <mechanicalReduction>1</mechanicalReduction>
    </actuator>
  </transmission>
  <!--link 2-->
  <link name="AR5_5_07R_link2">
    <visual>
      <geometry>
        <mesh filename="package://robot_model/meshes/AR5_P_R/AR5_5_07R_link2.stl" scale="0.001 0.001 0.001"/>
      </geometry>
      <origin rpy="0 0 0" xyz="0 0 0.0"/>
      <material name="white"/>
    </visual>
    <inertial>
      <mass value="2.3"/>
      <inertia ixx="0.01155422" ixy="0.00000028" ixz="-0.00000103" iyy="0.00995119" iyz="0.00083831" izz="0.00437076"/>
      <origin rpy="0 0 0" xyz="4.4999999999999996e-05 -0.002985 0.102801"/>
    </inertial>
    <collision>
      <geometry>
        <mesh filename="package://robot_model/meshes/AR5_P_R/AR5_5_07R_link2.stl" scale="0.001 0.001 0.001"/>
      </geometry>
      <origin rpy="0 0 0" xyz="0 0 0.0"/>
    </collision>
  </link>
  <joint name="AR5_5_07R_joint_3" type="revolute">
    <parent link="AR5_5_07R_link2"/>
    <child link="AR5_5_07R_link3"/>
    <limit effort="66" lower="-3.07" upper="3.07" velocity="4.71238898038469"/>
    <axis xyz="0 0 1"/>
    <origin rpy="0 0 0" xyz="0.0 0.0 0.314"/>
  </joint>
  <transmission name="rtran3">
    <type>transmission_interface/SimpleTransmission</type>
    <joint name="AR5_5_07R_joint_3">
      <hardwareInterface>EffortJointInterface</hardwareInterface>
    </joint>
    <actuator name="rmotor3">
      <hardwareInterface>EffortJointInterface</hardwareInterface>
      <mechanicalReduction>1</mechanicalReduction>
    </actuator>
  </transmission>
  <!--link 3-->
  <link name="AR5_5_07R_link3">
    <visual>
      <geometry>
        <mesh filename="package://robot_model/meshes/AR5_P_R/AR5_5_07R_link3.stl" scale="0.001 0.001 0.001"/>
      </geometry>
      <origin rpy="0 0 0" xyz="0 0 0"/>
      <material name="white"/>
    </visual>
    <inertial>
      <mass value="1.8"/>
      <inertia ixx="0.00478231" ixy="0.00001317" ixz="0.00033105" iyy="0.00432575" iyz="0.00002132" izz="0.00254969"/>
      <origin rpy="0 0 0" xyz="0.0073 -0.001371 -0.01502"/>
    </inertial>
    <collision>
      <geometry>
        <mesh filename="package://robot_model/meshes/AR5_P_R/AR5_5_07R_link3.stl" scale="0.001 0.001 0.001"/>
      </geometry>
      <origin rpy="0 0 0" xyz="0 0 0"/>
    </collision>
  </link>
  <joint name="AR5_5_07R_joint_4" type="revolute">
    <parent link="AR5_5_07R_link3"/>
    <child link="AR5_5_07R_link4"/>
    <limit effort="66" lower="-1.01" upper="2.5" velocity="5.235987755982989"/>
    <!--     lower="-1.0472" upper="1.0472" -->
    <axis xyz="0 1 0"/>
    <!--     <origin rpy="0 0 0" xyz=0.0105 0.0 0.0/> -->
    <origin rpy="0 0 0" xyz="0.0105 0.0 0.0"/>
  </joint>
  <transmission name="rtran4">
    <type>transmission_interface/SimpleTransmission</type>
    <joint name="AR5_5_07R_joint_4">
      <hardwareInterface>EffortJointInterface</hardwareInterface>
    </joint>
    <actuator name="rmotor4">
      <hardwareInterface>EffortJointInterface</hardwareInterface>
      <mechanicalReduction>1</mechanicalReduction>
    </actuator>
  </transmission>
  <!--link 4-->
  <link name="AR5_5_07R_link4">
    <visual>
      <geometry>
        <mesh filename="package://robot_model/meshes/AR5_P_R/AR5_5_07R_link4.stl" scale=".001 0.001 0.001"/>
      </geometry>
      <origin rpy="0 0 0" xyz="0.0 0.0 0.0"/>
      <material name="white"/>
    </visual>
    <inertial>
      <mass value="1.13"/>
      <inertia ixx="0.00352152" ixy="-0.00002411" ixz="-0.00015046" iyy="0.00266275" iyz="0.00025447" izz="0.00186915"/>
      <origin rpy="0 0 0" xyz="-0.007816 -0.002536 0.066782"/>
    </inertial>
    <collision>
      <geometry>
        <mesh filename="package://robot_model/meshes/AR5_P_R/AR5_5_07R_link4.stl" scale="0.001 0.001 0.001"/>
      </geometry>
      <origin rpy="0 0 0" xyz="0.0 0.0 0.0"/>
    </collision>
  </link>
  <joint name="AR5_5_07R_joint_5" type="revolute">
    <parent link="AR5_5_07R_link4"/>
    <child link="AR5_5_07R_link5"/>
    <limit effort="19" lower="-3.07" upper="3.07" velocity="4.1887902047863905"/>
    <axis xyz="0 0 1"/>
    <origin rpy="0 0 0" xyz="-0.0105 0.0 0.26"/>
  </joint>
  <transmission name="rtran5">
    <type>transmission_interface/SimpleTransmission</type>
    <joint name="AR5_5_07R_joint_5">
      <hardwareInterface>EffortJointInterface</hardwareInterface>
    </joint>
    <actuator name="rmotor5">
      <hardwareInterface>EffortJointInterface</hardwareInterface>
      <mechanicalReduction>1</mechanicalReduction>
    </actuator>
  </transmission>
  <!--link 5-->
  <link name="AR5_5_07R_link5">
    <visual>
      <geometry>
        <mesh filename="package://robot_model/meshes/AR5_P_R/AR5_5_07R_link5.stl" scale="0.001 0.001 0.001"/>
      </geometry>
      <origin rpy="0 0 0" xyz="0 0 0"/>
      <material name="white"/>
    </visual>
    <inertial>
      <mass value="1.19"/>
      <inertia ixx="0.00239004" ixy="-0.00000866" ixz="0.00001606" iyy="0.00196096" iyz="-0.00001370" izz="0.00150238"/>
      <origin rpy="0 0 0" xyz="0.00022600000000000002 -0.002462 -0.081161"/>
    </inertial>
    <collision>
      <geometry>
        <mesh filename="package://robot_model/meshes/AR5_P_R/AR5_5_07R_link5.stl" scale="0.001 0.001 0.001"/>
      </geometry>
      <origin rpy="0 0 0" xyz="0 0 0"/>
    </collision>
  </link>
  <joint name="AR5_5_07R_joint_6" type="revolute">
    <parent link="AR5_5_07R_link5"/>
    <child link="AR5_5_07R_link6"/>
    <limit effort="19" lower="-1.01" upper="1.01" velocity="4.1887902047863905"/>
    <axis xyz="0 1 0"/>
    <origin rpy="0.0 0.0 0" xyz="0.0 0.0 0.0"/>
  </joint>
  <transmission name="rtran6">
    <type>transmission_interface/SimpleTransmission</type>
    <joint name="AR5_5_07R_joint_6">
      <hardwareInterface>EffortJointInterface</hardwareInterface>
    </joint>
    <actuator name="rmotor6">
      <hardwareInterface>EffortJointInterface</hardwareInterface>
      <mechanicalReduction>1</mechanicalReduction>
    </actuator>
  </transmission>
  <!--link 6-->
  <link name="AR5_5_07R_link6">
    <visual>
      <geometry>
        <mesh filename="package://robot_model/meshes/AR5_P_R/AR5_5_07R_link6.stl" scale="0.001 0.001 0.001"/>
      </geometry>
      <origin rpy="0 0 0" xyz="0 0 0"/>
      <material name="white"/>
    </visual>
    <inertial>
      <mass value="0.82"/>
      <inertia ixx="0.00060720" ixy="0.00000824" ixz="-0.00000087" iyy="0.00066149" iyz="0.00000017" izz="0.00066643"/>
      <origin rpy="0 0 0" xyz="0.0070940000000000005 -0.000714 4.2000000000000004e-05"/>
    </inertial>
    <collision>
      <geometry>
        <mesh filename="package://robot_model/meshes/AR5_P_R/AR5_5_07R_link6.stl" scale="0.001 0.001 0.001"/>
      </geometry>
      <origin rpy="0 0 0" xyz="0 0 0"/>
    </collision>
  </link>
  <joint name="AR5_5_07R_joint_7" type="revolute">
    <parent link="AR5_5_07R_link6"/>
    <child link="AR5_5_07R_link7"/>
    <limit effort="19" lower="-1.01" upper="1.01" velocity="4.1887902047863905"/>
    <axis xyz="1 0 0"/>
    <origin rpy="0.0 0.0 0" xyz="0.0 0.0 0.0"/>
  </joint>
  <transmission name="rtran7">
    <type>transmission_interface/SimpleTransmission</type>
    <joint name="AR5_5_07R_joint_7">
      <hardwareInterface>EffortJointInterface</hardwareInterface>
    </joint>
    <actuator name="rmotor7">
      <hardwareInterface>EffortJointInterface</hardwareInterface>
      <mechanicalReduction>1</mechanicalReduction>
    </actuator>
  </transmission>
  <!--link 7-->
  <link name="AR5_5_07R_link7">
    <visual>
      <geometry>
        <mesh filename="package://robot_model/meshes/AR5_P_R/AR5_5_07R_link7.stl" scale="0.001 0.001 0.001"/>
      </geometry>
      <origin rpy="0 0 0" xyz="0.0 0.0 0.0"/>
      <material name="white"/>
    </visual>
    <inertial>
      <mass value="0.32"/>
      <inertia ixx="0.00043649" ixy="0.00000037" ixz="0.00001247" iyy="0.00067127" iyz="0.00000047" izz="0.00041742"/>
      <origin rpy="0 0 0" xyz="-0.002337 6e-06 0.051713999999999996"/>
    </inertial>
    <collision>
      <geometry>
        <mesh filename="package://robot_model/meshes/AR5_P_R/AR5_5_07R_link7.stl" scale="0.001 0.001 0.001"/>
      </geometry>
      <origin rpy="0 0 0" xyz="0.0 0.0 0.0"/>
    </collision>
  </link>
  <joint name="AR5_5_07R_tcp_joint" type="fixed">
    <parent link="AR5_5_07R_link7"/>
    <child link="AR5_5_07R_tcp"/>
    <origin rpy="0 0 0" xyz="0.0 0.0 0.092"/>
  </joint>
  <link name="AR5_5_07R_tcp">
    <inertial>
      <mass value="0.0"/>
      <inertia ixx="1e-6" ixy="0" ixz="0" iyy="1e-6" iyz="0" izz="1e-6"/>
    </inertial>
  </link>

  <!-- 左力传感器+夹爪部分 -->
  <joint name="left_flange_base_joint" type="fixed">
    <parent link="AR5_5_07L_tcp"/>
    <child link="left_flange_link"/>
    <origin xyz= "0 0.0 0.005" rpy = "0 0 0"/>
  </joint>
  <link name="left_flange_link">
    <visual>
      <geometry>
        <mesh filename="package://robot_model/meshes/flange.STL" scale="1 1 1"/>
      </geometry>
      <origin rpy="0 0 0" xyz="0 0 0"/>
      <material name="grey">
        <color rgba="0.5 0.5 0.5 1"/>
      </material>
    </visual>
    <inertial>
      <mass value="0.2"/>
      <inertia ixx="0.0005" ixy="0" ixz="0" iyy="0.0005" iyz="0" izz="0.0005"/>
      <origin rpy="0 0 0" xyz="0 0 0"/>
    </inertial>
    <collision>
      <geometry>
        <mesh filename="package://robot_model/meshes/flange.STL" scale="1 1 1"/>
      </geometry>
      <origin rpy="0 0 0" xyz="0 0 0"/>
    </collision>
  </link>

  <joint name="left_gripper_base_joint" type="fixed">
    <parent link="left_flange_link"/>
    <child link="Lbase_link"/>
    <origin xyz= "0 0 0.0375" rpy = "0 0 0"/>
  </joint>
  <link name="Lbase_link">
    <inertial>
      <origin rpy="0 0 0" xyz="-3.5971E-08 6.1102E-06 0.055353"/>
      <mass value="0.47237"/>
      <inertia ixx="0.00054317" ixy="-9.222E-09" ixz="2.4709E-09" iyy="0.00068105" iyz="-1.5078E-07" izz="0.00038996"/>
    </inertial>
    <visual>
      <origin rpy="0 0 0" xyz="0 0 0"/>
      <geometry>
        <mesh filename="package://robot_model/meshes/CTM_2F_110/base_link.STL"/>
      </geometry>
      <material name="">
        <color rgba="0.10196 0.10196 0.10196 1"/>
      </material>
    </visual>
    <collision>
      <origin rpy="0 0 0" xyz="0 0 0"/>
      <geometry>
        <mesh filename="package://robot_model/meshes/CTM_2F_110/base_link.STL"/>
      </geometry>
    </collision>
  </link>
  <link name="Lleftout_Link">
    <inertial>
      <origin rpy="0 0 0" xyz="-0.0068505 0.028833 -8.8224E-08"/>
      <mass value="0.010089"/>
      <inertia ixx="3.7101E-06" ixy="6.4157E-07" ixz="9.3979E-12" iyy="1.1175E-06" iyz="-4.9338E-11" izz="3.12E-06"/>
    </inertial>
    <visual>
      <origin rpy="0 0 0" xyz="0 0 0"/>
      <geometry>
        <mesh filename="package://robot_model/meshes/CTM_2F_110/leftout_Link.STL"/>
      </geometry>
      <material name="">
        <color rgba="0.66667 0.69804 0.76863 1"/>
      </material>
    </visual>
    <collision>
      <origin rpy="0 0 0" xyz="0 0 0"/>
      <geometry>
        <mesh filename="package://robot_model/meshes/CTM_2F_110/leftout_Link.STL"/>
      </geometry>
    </collision>
  </link>
  <link name="Lleftinn_Link">
    <inertial>
      <origin rpy="0 0 0" xyz="-0.030058 0.022769 5.1949E-07"/>
      <mass value="0.018332"/>
      <inertia ixx="6.7469E-06" ixy="3.6682E-06" ixz="9.1466E-11" iyy="3.9665E-06" iyz="-4.1418E-10" izz="9.6683E-06"/>
    </inertial>
    <visual>
      <origin rpy="0 0 0" xyz="0 0 0"/>
      <geometry>
        <mesh filename="package://robot_model/meshes/CTM_2F_110/leftinn_Link.STL"/>
      </geometry>
      <material name="">
        <color rgba="0.79216 0.81961 0.93333 1"/>
      </material>
    </visual>
    <collision>
      <origin rpy="0 0 0" xyz="0 0 0"/>
      <geometry>
        <mesh filename="package://robot_model/meshes/CTM_2F_110/leftinn_Link.STL"/>
      </geometry>
    </collision>
  </link>
  <link name="Lleft_pad">
    <inertial>
      <origin rpy="0 0 0" xyz="0.013913 -0.019134 4.0039E-06"/>
      <mass value="0.018332"/>
      <inertia ixx="6.7469E-06" ixy="3.6682E-06" ixz="8.8651E-11" iyy="3.9665E-06" iyz="-4.0981E-10" izz="9.6683E-06"/>
    </inertial>
    <visual>
      <origin rpy="0 0 0" xyz="0 0 0"/>
      <geometry>
        <mesh filename="package://robot_model/meshes/CTM_2F_110/left_pad.STL"/>
      </geometry>
      <material name="">
        <color rgba="0.79216 0.81961 0.93333 1"/>
      </material>
    </visual>
    <collision>
      <origin rpy="0 0 0" xyz="0 0 0"/>
      <geometry>
        <mesh filename="package://robot_model/meshes/CTM_2F_110/left_pad.STL"/>
      </geometry>
    </collision>
  </link>
  <link name="Lleft_kckle">
    <inertial>
      <origin rpy="0 0 0" xyz="-0.0057173 0.023663 -3.1623E-06"/>
      <mass value="0.012137"/>
      <inertia ixx="1.086E-05" ixy="1.05E-06" ixz="6.9749E-10" iyy="6.7673E-06" iyz="-7.7731E-10" izz="5.0823E-06"/>
    </inertial>
    <visual>
      <origin rpy="0 0 0" xyz="0 0 0"/>
      <geometry>
        <mesh filename="package://robot_model/meshes/CTM_2F_110/left_kckle.STL"/>
      </geometry>
      <material name="">
        <color rgba="0.2 0.2 0.2 1"/>
      </material>
    </visual>
    <collision>
      <origin rpy="0 0 0" xyz="0 0 0"/>
      <geometry>
        <mesh filename="package://robot_model/meshes/CTM_2F_110/left_kckle.STL"/>
      </geometry>
    </collision>
  </link>
  <link name="Lrightout_Link">
    <inertial>
      <origin rpy="0 0 0" xyz="-0.0068505 0.028833 -8.8224E-08"/>
      <mass value="0.010089"/>
      <inertia ixx="3.7101E-06" ixy="6.4157E-07" ixz="9.3979E-12" iyy="1.1175E-06" iyz="-4.9338E-11" izz="3.12E-06"/>
    </inertial>
    <visual>
      <origin rpy="0 0 0" xyz="0 0 0"/>
      <geometry>
        <mesh filename="package://robot_model/meshes/CTM_2F_110/rightout_Link.STL"/>
      </geometry>
      <material name="">
        <color rgba="0.66667 0.69804 0.76863 1"/>
      </material>
    </visual>
    <collision>
      <origin rpy="0 0 0" xyz="0 0 0"/>
      <geometry>
        <mesh filename="package://robot_model/meshes/CTM_2F_110/rightout_Link.STL"/>
      </geometry>
    </collision>
  </link>
  <link name="Lrightinn_Link">
    <inertial>
      <origin rpy="0 0 0" xyz="-0.030058 0.022769 5.1949E-07"/>
      <mass value="0.018332"/>
      <inertia ixx="6.7469E-06" ixy="3.6682E-06" ixz="9.1466E-11" iyy="3.9665E-06" iyz="-4.1418E-10" izz="9.6683E-06"/>
    </inertial>
    <visual>
      <origin rpy="0 0 0" xyz="0 0 0"/>
      <geometry>
        <mesh filename="package://robot_model/meshes/CTM_2F_110/rightinn_Link.STL"/>
      </geometry>
      <material name="">
        <color rgba="0.79216 0.81961 0.93333 1"/>
      </material>
    </visual>
    <collision>
      <origin rpy="0 0 0" xyz="0 0 0"/>
      <geometry>
        <mesh filename="package://robot_model/meshes/CTM_2F_110/rightinn_Link.STL"/>
      </geometry>
    </collision>
  </link>
  <link name="Lright_pad">
    <inertial>
      <origin rpy="0 0 0" xyz="0.013913 -0.019134 4.0039E-06"/>
      <mass value="0.018332"/>
      <inertia ixx="6.7469E-06" ixy="3.6682E-06" ixz="8.8651E-11" iyy="3.9665E-06" iyz="-4.0981E-10" izz="9.6683E-06"/>
    </inertial>
    <visual>
      <origin rpy="0 0 0" xyz="0 0 0"/>
      <geometry>
        <mesh filename="package://robot_model/meshes/CTM_2F_110/right_pad.STL"/>
      </geometry>
      <material name="">
        <color rgba="0.79216 0.81961 0.93333 1"/>
      </material>
    </visual>
    <collision>
      <origin rpy="0 0 0" xyz="0 0 0"/>
      <geometry>
        <mesh filename="package://robot_model/meshes/CTM_2F_110/right_pad.STL"/>
      </geometry>
    </collision>
  </link>
  <link name="Lright_kckle">
    <inertial>
      <origin rpy="0 0 0" xyz="-0.0057173 0.023663 -3.1623E-06"/>
      <mass value="0.012137"/>
      <inertia ixx="1.086E-05" ixy="1.05E-06" ixz="6.9749E-10" iyy="6.7673E-06" iyz="-7.7731E-10" izz="5.0823E-06"/>
    </inertial>
    <visual>
      <origin rpy="0 0 0" xyz="0 0 0"/>
      <geometry>
        <mesh filename="package://robot_model/meshes/CTM_2F_110/right_kckle.STL"/>
      </geometry>
      <material name="">
        <color rgba="0.2 0.2 0.2 1"/>
      </material>
    </visual>
    <collision>
      <origin rpy="0 0 0" xyz="0 0 0"/>
      <geometry>
        <mesh filename="package://robot_model/meshes/CTM_2F_110/right_kckle.STL"/>
      </geometry>
    </collision>
  </link>
  <joint name="Lfinger_joint" type="revolute">
    <origin rpy="1.5708 0 -3.1416" xyz="-0.057 0 0.07825"/>
    <parent link="Lbase_link"/>
    <child link="Lleftout_Link"/>
    <axis xyz="0 0 -1"/>
    <limit effort="1000" lower="0" upper="1" velocity="2.0"/>
    <dynamics damping="2.0" friction="50.0" />
  </joint>
  <joint name="Lleft_kckle_joint" type="revolute">
    <origin rpy="1.5707963267948966 0 -3.141592653589793" xyz="-0.024 0 0.09025"/>
    <parent link="Lbase_link"/>
    <child link="Lleft_kckle"/>
    <axis xyz="0 0 -1"/>
    <limit effort="1000" lower="-1" upper="1" velocity="2.0"/>
    <mimic joint="Lfinger_joint" multiplier="1" offset="0"/>
    <dynamics damping="2.0" friction="50.0" />
  </joint>
  <joint name="Lleftinn_joint" type="revolute">
    <origin rpy="0 0 0" xyz="-0.010946 0.0539 0"/>
    <parent link="Lleftout_Link"/>
    <child link="Lleftinn_Link"/>
    <axis xyz="0 0 -1"/>
    <limit effort="1000" lower="-1" upper="0" velocity="2.0"/>
    <mimic joint="Lfinger_joint" multiplier="-1" offset="0"/>
    <dynamics damping="2.0" friction="50.0" />
  </joint>
  <joint name="Lleft_pad_joint" type="fixed">
    <origin rpy="0 0 0" xyz="-0.04597 0.041903 0"/>
    <parent link="Lleftinn_Link"/>
    <child link="Lleft_pad"/>
    <axis xyz="0 0 0"/>
  </joint>
  <joint name="Lrightout_joint" type="revolute">
    <origin rpy="1.5708 0 0" xyz="0.057 0 0.07825"/>
    <parent link="Lbase_link"/>
    <child link="Lrightout_Link"/>
    <axis xyz="0 0 -1"/>
    <limit effort="1000" lower="0" upper="1" velocity="2.0"/>
    <mimic joint="Lfinger_joint" multiplier="1" offset="0"/>
    <dynamics damping="2.0" friction="50.0" />
  </joint>
  <joint name="Lright_kckle_joint" type="revolute">
    <origin rpy="1.5707963267948966 0 -0.0" xyz="0.024 0 0.09025"/>
    <parent link="Lbase_link"/>
    <child link="Lright_kckle"/>
    <axis xyz="0 0 -1"/>
    <limit effort="1000" lower="-1" upper="1" velocity="2.0"/>
    <mimic joint="Lfinger_joint" multiplier="1" offset="0"/>
    <dynamics damping="2.0" friction="50.0" />
  </joint>
  <joint name="Lrightinn_joint" type="revolute">
    <origin rpy="0 0 0" xyz="-0.010946 0.0539 0"/>
    <parent link="Lrightout_Link"/>
    <child link="Lrightinn_Link"/>
    <axis xyz="0 0 -1"/>
    <limit effort="1000" lower="-1" upper="0" velocity="2.0"/>
    <mimic joint="Lfinger_joint" multiplier="-1" offset="0"/>
    <dynamics damping="2.0" friction="50.0" />
  </joint>
  <joint name="Lright_pad_joint" type="fixed">
    <origin rpy="0 0 0" xyz="-0.04597 0.041903 0"/>
    <parent link="Lrightinn_Link"/>
    <child link="Lright_pad"/>
    <axis xyz="0 0 0"/>
  </joint>


  <!-- 右力传感器+夹爪部分 -->
  <joint name="right_flange_base_joint" type="fixed">
    <parent link="AR5_5_07R_tcp"/>
    <child link="right_flange_link"/>
    <origin xyz= "0 0.0 0.005" rpy = "-1.5708 -1.5708 0"/>
  </joint>
  <link name="right_flange_link">
    <visual>
      <geometry>
        <mesh filename="package://robot_model/meshes/flange.dae" scale="1 1 1"/>
      </geometry>
      <origin rpy="0 0 0" xyz="0 0 0"/>
      <material name="grey">
        <color rgba="0.5 0.5 0.5 1"/>
      </material>
    </visual>
    <inertial>
      <mass value="0.2"/>
      <inertia ixx="0.0005" ixy="0" ixz="0" iyy="0.0005" iyz="0" izz="0.0005"/>
      <origin rpy="0 0 0" xyz="0 0 0"/>
    </inertial>
    <collision>
      <geometry>
        <mesh filename="package://robot_model/meshes/flange.dae" scale="1 1 1"/>
      </geometry>
      <origin rpy="0 0 0" xyz="0 0 0"/>
    </collision>
  </link>

  <joint name="right_gripper_base_joint" type="fixed">
    <parent link="right_flange_link"/>
    <child link="Rbase_link"/>
    <origin xyz= "0.036 0.0 0.0" rpy = "-1.5708 0 -1.5708"/>
  </joint>
  <link name="Rbase_link">
    <inertial>
      <origin rpy="0 0 0" xyz="-3.5971E-08 6.1102E-06 0.055353"/>
      <mass value="0.47237"/>
      <inertia ixx="0.00054317" ixy="-9.222E-09" ixz="2.4709E-09" iyy="0.00068105" iyz="-1.5078E-07" izz="0.00038996"/>
    </inertial>
    <visual>
      <origin rpy="0 0 0" xyz="0 0 0"/>
      <geometry>
        <mesh filename="package://robot_model/meshes/CTM_2F_110/base_link.STL"/>
      </geometry>
      <material name="">
        <color rgba="0.10196 0.10196 0.10196 1"/>
      </material>
    </visual>
    <collision>
      <origin rpy="0 0 0" xyz="0 0 0"/>
      <geometry>
        <mesh filename="package://robot_model/meshes/CTM_2F_110/base_link.STL"/>
      </geometry>
    </collision>
  </link>
  <link name="Rleftout_Link">
    <inertial>
      <origin rpy="0 0 0" xyz="-0.0068505 0.028833 -8.8224E-08"/>
      <mass value="0.010089"/>
      <inertia ixx="3.7101E-06" ixy="6.4157E-07" ixz="9.3979E-12" iyy="1.1175E-06" iyz="-4.9338E-11" izz="3.12E-06"/>
    </inertial>
    <visual>
      <origin rpy="0 0 0" xyz="0 0 0"/>
      <geometry>
        <mesh filename="package://robot_model/meshes/CTM_2F_110/leftout_Link.STL"/>
      </geometry>
      <material name="">
        <color rgba="0.66667 0.69804 0.76863 1"/>
      </material>
    </visual>
    <collision>
      <origin rpy="0 0 0" xyz="0 0 0"/>
      <geometry>
        <mesh filename="package://robot_model/meshes/CTM_2F_110/leftout_Link.STL"/>
      </geometry>
    </collision>
  </link>
  <link name="Rleftinn_Link">
    <inertial>
      <origin rpy="0 0 0" xyz="-0.030058 0.022769 5.1949E-07"/>
      <mass value="0.018332"/>
      <inertia ixx="6.7469E-06" ixy="3.6682E-06" ixz="9.1466E-11" iyy="3.9665E-06" iyz="-4.1418E-10" izz="9.6683E-06"/>
    </inertial>
    <visual>
      <origin rpy="0 0 0" xyz="0 0 0"/>
      <geometry>
        <mesh filename="package://robot_model/meshes/CTM_2F_110/leftinn_Link.STL"/>
      </geometry>
      <material name="">
        <color rgba="0.79216 0.81961 0.93333 1"/>
      </material>
    </visual>
    <collision>
      <origin rpy="0 0 0" xyz="0 0 0"/>
      <geometry>
        <mesh filename="package://robot_model/meshes/CTM_2F_110/leftinn_Link.STL"/>
      </geometry>
    </collision>
  </link>
  <link name="Rleft_pad">
    <inertial>
      <origin rpy="0 0 0" xyz="0.013913 -0.019134 4.0039E-06"/>
      <mass value="0.018332"/>
      <inertia ixx="6.7469E-06" ixy="3.6682E-06" ixz="8.8651E-11" iyy="3.9665E-06" iyz="-4.0981E-10" izz="9.6683E-06"/>
    </inertial>
    <visual>
      <origin rpy="0 0 0" xyz="0 0 0"/>
      <geometry>
        <mesh filename="package://robot_model/meshes/CTM_2F_110/left_pad.STL"/>
      </geometry>
      <material name="">
        <color rgba="0.79216 0.81961 0.93333 1"/>
      </material>
    </visual>
    <collision>
      <origin rpy="0 0 0" xyz="0 0 0"/>
      <geometry>
        <mesh filename="package://robot_model/meshes/CTM_2F_110/left_pad.STL"/>
      </geometry>
    </collision>
  </link>
  <link name="Rleft_kckle">
    <inertial>
      <origin rpy="0 0 0" xyz="-0.0057173 0.023663 -3.1623E-06"/>
      <mass value="0.012137"/>
      <inertia ixx="1.086E-05" ixy="1.05E-06" ixz="6.9749E-10" iyy="6.7673E-06" iyz="-7.7731E-10" izz="5.0823E-06"/>
    </inertial>
    <visual>
      <origin rpy="0 0 0" xyz="0 0 0"/>
      <geometry>
        <mesh filename="package://robot_model/meshes/CTM_2F_110/left_kckle.STL"/>
      </geometry>
      <material name="">
        <color rgba="0.2 0.2 0.2 1"/>
      </material>
    </visual>
    <collision>
      <origin rpy="0 0 0" xyz="0 0 0"/>
      <geometry>
        <mesh filename="package://robot_model/meshes/CTM_2F_110/left_kckle.STL"/>
      </geometry>
    </collision>
  </link>
  <link name="Rrightout_Link">
    <inertial>
      <origin rpy="0 0 0" xyz="-0.0068505 0.028833 -8.8224E-08"/>
      <mass value="0.010089"/>
      <inertia ixx="3.7101E-06" ixy="6.4157E-07" ixz="9.3979E-12" iyy="1.1175E-06" iyz="-4.9338E-11" izz="3.12E-06"/>
    </inertial>
    <visual>
      <origin rpy="0 0 0" xyz="0 0 0"/>
      <geometry>
        <mesh filename="package://robot_model/meshes/CTM_2F_110/rightout_Link.STL"/>
      </geometry>
      <material name="">
        <color rgba="0.66667 0.69804 0.76863 1"/>
      </material>
    </visual>
    <collision>
      <origin rpy="0 0 0" xyz="0 0 0"/>
      <geometry>
        <mesh filename="package://robot_model/meshes/CTM_2F_110/rightout_Link.STL"/>
      </geometry>
    </collision>
  </link>
  <link name="Rrightinn_Link">
    <inertial>
      <origin rpy="0 0 0" xyz="-0.030058 0.022769 5.1949E-07"/>
      <mass value="0.018332"/>
      <inertia ixx="6.7469E-06" ixy="3.6682E-06" ixz="9.1466E-11" iyy="3.9665E-06" iyz="-4.1418E-10" izz="9.6683E-06"/>
    </inertial>
    <visual>
      <origin rpy="0 0 0" xyz="0 0 0"/>
      <geometry>
        <mesh filename="package://robot_model/meshes/CTM_2F_110/rightinn_Link.STL"/>
      </geometry>
      <material name="">
        <color rgba="0.79216 0.81961 0.93333 1"/>
      </material>
    </visual>
    <collision>
      <origin rpy="0 0 0" xyz="0 0 0"/>
      <geometry>
        <mesh filename="package://robot_model/meshes/CTM_2F_110/rightinn_Link.STL"/>
      </geometry>
    </collision>
  </link>
  <link name="Rright_pad">
    <inertial>
      <origin rpy="0 0 0" xyz="0.013913 -0.019134 4.0039E-06"/>
      <mass value="0.018332"/>
      <inertia ixx="6.7469E-06" ixy="3.6682E-06" ixz="8.8651E-11" iyy="3.9665E-06" iyz="-4.0981E-10" izz="9.6683E-06"/>
    </inertial>
    <visual>
      <origin rpy="0 0 0" xyz="0 0 0"/>
      <geometry>
        <mesh filename="package://robot_model/meshes/CTM_2F_110/right_pad.STL"/>
      </geometry>
      <material name="">
        <color rgba="0.79216 0.81961 0.93333 1"/>
      </material>
    </visual>
    <collision>
      <origin rpy="0 0 0" xyz="0 0 0"/>
      <geometry>
        <mesh filename="package://robot_model/meshes/CTM_2F_110/right_pad.STL"/>
      </geometry>
    </collision>
  </link>
  <link name="Rright_kckle">
    <inertial>
      <origin rpy="0 0 0" xyz="-0.0057173 0.023663 -3.1623E-06"/>
      <mass value="0.012137"/>
      <inertia ixx="1.086E-05" ixy="1.05E-06" ixz="6.9749E-10" iyy="6.7673E-06" iyz="-7.7731E-10" izz="5.0823E-06"/>
    </inertial>
    <visual>
      <origin rpy="0 0 0" xyz="0 0 0"/>
      <geometry>
        <mesh filename="package://robot_model/meshes/CTM_2F_110/right_kckle.STL"/>
      </geometry>
      <material name="">
        <color rgba="0.2 0.2 0.2 1"/>
      </material>
    </visual>
    <collision>
      <origin rpy="0 0 0" xyz="0 0 0"/>
      <geometry>
        <mesh filename="package://robot_model/meshes/CTM_2F_110/right_kckle.STL"/>
      </geometry>
    </collision>
  </link>
  <joint name="Rfinger_joint" type="revolute">
    <origin rpy="1.5708 0 -3.1416" xyz="-0.057 0 0.07825"/>
    <parent link="Rbase_link"/>
    <child link="Rleftout_Link"/>
    <axis xyz="0 0 -1"/>
    <limit effort="1000" lower="0" upper="1" velocity="2.0"/>
    <dynamics damping="2.0" friction="50.0" />
  </joint>
  <joint name="Rleft_kckle_joint" type="revolute">
    <origin rpy="1.5707963267948966 0 -3.141592653589793" xyz="-0.024 0 0.09025"/>
    <parent link="Rbase_link"/>
    <child link="Rleft_kckle"/>
    <axis xyz="0 0 -1"/>
    <limit effort="1000" lower="-1" upper="1" velocity="2.0"/>
    <mimic joint="Rfinger_joint" multiplier="1" offset="0"/>
    <dynamics damping="2.0" friction="50.0" />
  </joint>
  <joint name="Rleftinn_joint" type="revolute">
    <origin rpy="0 0 0" xyz="-0.010946 0.0539 0"/>
    <parent link="Rleftout_Link"/>
    <child link="Rleftinn_Link"/>
    <axis xyz="0 0 -1"/>
    <limit effort="1000" lower="-1" upper="0" velocity="2.0"/>
    <mimic joint="Rfinger_joint" multiplier="-1" offset="0"/>
    <dynamics damping="2.0" friction="50.0" />
  </joint>
  <joint name="Rleft_pad_joint" type="fixed">
    <origin rpy="0 0 0" xyz="-0.04597 0.041903 0"/>
    <parent link="Rleftinn_Link"/>
    <child link="Rleft_pad"/>
    <axis xyz="0 0 0"/>
  </joint>
  <joint name="Rrightout_joint" type="revolute">
    <origin rpy="1.5708 0 0" xyz="0.057 0 0.07825"/>
    <parent link="Rbase_link"/>
    <child link="Rrightout_Link"/>
    <axis xyz="0 0 -1"/>
    <limit effort="1000" lower="0" upper="1" velocity="2.0"/>
    <mimic joint="Rfinger_joint" multiplier="1" offset="0"/>
    <dynamics damping="2.0" friction="50.0" />
  </joint>
  <joint name="Rright_kckle_joint" type="revolute">
    <origin rpy="1.5707963267948966 0 -0.0" xyz="0.024 0 0.09025"/>
    <parent link="Rbase_link"/>
    <child link="Rright_kckle"/>
    <axis xyz="0 0 -1"/>
    <limit effort="1000" lower="-1" upper="1" velocity="2.0"/>
    <mimic joint="Rfinger_joint" multiplier="1" offset="0"/>
    <dynamics damping="2.0" friction="50.0" />
  </joint>
  <joint name="Rrightinn_joint" type="revolute">
    <origin rpy="0 0 0" xyz="-0.010946 0.0539 0"/>
    <parent link="Rrightout_Link"/>
    <child link="Rrightinn_Link"/>
    <axis xyz="0 0 -1"/>
    <limit effort="1000" lower="-1" upper="0" velocity="2.0"/>
    <mimic joint="Rfinger_joint" multiplier="-1" offset="0"/>
    <dynamics damping="2.0" friction="50.0" />
  </joint>
  <joint name="Rright_pad_joint" type="fixed">
    <origin rpy="0 0 0" xyz="-0.04597 0.041903 0"/>
    <parent link="Rrightinn_Link"/>
    <child link="Rright_pad"/>
    <axis xyz="0 0 0"/>
  </joint>
  
</robot>